Workbook
Name Debt_Amt3: 'Input Assumptions'!$G$49
Name AUV_Start: 'Input Assumptions'!$D$11
Name Inv_Days: 'Input Assumptions'!$H$9
Name Debt_Rate1: 'Input Assumptions'!$E$51
Name Equity_Cash: 'Input Assumptions'!$E$48
Name Gross_Sales: 'Input Assumptions'!$D$9
Name Pre_Tax_Profit_Target: 'Input Assumptions'!$E$37:$I$37
Name CustAudit_Start: Audit!$F$13
Name BS_Check_II: 'Balance Sheet'!$B$49
Name Growth_Rate: 'Input Assumptions'!$E$21:$I$21
Name Operating_Expenses: 'Input Assumptions'!$E$34:$I$34
Name Acc_Pay_Days_Mat: 'Input Assumptions'!$H$8
Name Direct_Labor_Cost: 'Input Assumptions'!$E$29:$I$29
Name Nav_Valuation: Model!$A$304
Name Nav_Debt: Model!$A$189
Name Debt_Term1: 'Input Assumptions'!$E$50
Name Nav_ROI: Model!$A$282
Name Facilities: 'Input Assumptions'!$E$30:$I$30
Name EBITDA_Multiple: 'Input Assumptions'!$D$13
Name Marketing: 'Input Assumptions'!$E$31:$I$31
Name Workings_BS: Model!$B$90
Name BS_Check: Model!$D$117
Name Fin_Year_End: 'Input Assumptions'!$D$8
Name Audit_SumChk: Audit!$B$9
Name Distributions: 'Input Assumptions'!$E$55:$I$55
Name Payroll_Tax: 'Input Assumptions'!$E$33:$I$33
Name Audit_Start: Audit!$B$13
Name Nav_BS: Model!$A$90
Name Management_Salaries: 'Input Assumptions'!$E$32:$I$32
Name LTGR: Model!$E$306
Name Company_Name: 'Input Assumptions'!$E$4
Name Start_Date: 'Input Assumptions'!$D$7
Name Nav_CF: Model!$A$119
Name Other_Inv_WorkCapital: 'Input Assumptions'!$E$44:$I$44
Name Debt_Amt1: 'Input Assumptions'!$E$49
Name Breakeven: Model!$C$250
Name Royalty_Fee: 'Input Assumptions'!$E$24:$I$24
Name Nav_CT: Model!$A$146
Name Nav_Breakeven: Model!$A$245
Name Fixed_Assets: 'Input Assumptions'!$E$42:$I$42
Name CustAudit_SumChk: Audit!$F$9
Name WACC: Model!$E$305
Name Shareholder_Salary_Adj: 'Input Assumptions'!$E$38:$I$38
Name AUV_Reached: 'Input Assumptions'!$D$10
Name Workings_PL: Model!$B$15
Name Acc_Rec_Days: 'Input Assumptions'!$H$7
Name Debt_Term3: 'Input Assumptions'!$G$50
Name Debt_Rate2: 'Input Assumptions'!$F$51
Name Depreciation_Rate: 'Input Assumptions'!$H$10
Name Other_Inv_Spending: 'Input Assumptions'!$E$43:$I$43
Name Marketing_Fee: 'Input Assumptions'!$E$25:$I$25
Name Corp_Tax_Pay_Lag: 'Input Assumptions'!$H$11
Name Debt_Rate3: 'Input Assumptions'!$G$51
Name Debt_Term2: 'Input Assumptions'!$F$50
Name CT_Sum: Model!$B$85
Name Nav_PL: Model!$A$15
Name Materials_COGs: 'Input Assumptions'!$E$28:$I$28
Name Corp_Tax: 'Input Assumptions'!$D$12
Name Nav_WC: Model!$A$161
Name Debt_Amt2: 'Input Assumptions'!$F$49

Sheet Start Here!
C2: <<<<Click here to watch our introduction video>>>>

Sheet Glossary
B2: Key Terms and Definitions
B4: Term | C4: Definition | D4: Benchmark
B5: Payback period | C5: The payback period is a financial metric used to evaluate the time it takes for an investment to generate an amount of money equal to the original investment cost. In other words, it calculates how long it takes for an investor to recoup the initial outlay. | D5: 4-7 years
B6: EBITDA | C6: A way to look at a business's earnings before considering interest, taxes, depreciation, and amortization. It's like a scorecard that tells you how much money the core operations of a small business made, without getting into the details of certain financial expenses and accounting practices. It helps provide a clearer picture of the business's operational performance. | D6: 10-20% of gross revenues
B7: Adjusted (Adj) Net Profit Before Tax | C7: Net Profit Before Tax is the earnings after depreciation, amortization, and interest payments are deducted. The Net Profit Before Tax is 'adjusted' to account for cases where the owner decides to perform a role in the business for which they receive no salary or under salary. By adjusting the Net Profit Before Tax, you can better understand the 'true' performance of the business. | D7: 10%-15% of gross revenues
B8: Shareholder salary adjustment (+=underpayed) | C8: Sometimes a business owner will decide to perform a job within the business that should pay a certain salary per year, but they go without pay instead in order to preserve capital (sweat equity). This is the same as putting that amount into the business as an investor and hiring someone else to perform the role. It is key that we account for this so that you can understand the ‘true’ investment to calculate your potential returns as well as to calculate the ‘true’ pre-tax net income to understand how the business is actually performing. If the adjustment is positive, that means that the owner/operator was underpaid. | D8: Specific to each investor's individual case
B9: EBITDA Multiple | C9: A number that tells you how much people are willing to pay for a business compared to its EBITDA. This multiple can give a general idea of how valuable the market thinks a business is relative to its earnings. Think of it like a price tag: if the multiple is higher, the market generally sees the business as more valuable for each dollar it earns. | D9: 4x-7x depending on the franchise
B10: Average Unit Volume (AUV) | C10: In the franchise industry, "average unit volume" (AUV) refers to the average sales generated by a single franchise unit over a specified period, usually a year. It provides a measure of the financial performance and potential profitability of individual franchise units. | D10: See Input Assumptions sheet
B11: Operating Expenses - Direct Labor Cost | C11: Total "gross wages" paid to anyone who spends more than 50% of their time working on revenue producing activities. We do not recommend adding payroll taxes and benefits to this number since it clouds the simple decision making that can come from the Direct LER (labor efficiency ratio). | D11: Generally 25-30% of Gross Sales
B12: Operating Expenses - Facilities | C12: Total costs related to rent, utilities, telecommunications, IT costs, and vehicle fleet in the business. | D12: Individual franchise unit specific
B13: Equity - Cash | C13: The outside equity you invest into the business | D13: Assuming financing, typically 25% of total franchise investment cost.
B14: Core Capital | C14: Monthly operating expenses and labor expenses in cash and nothing drawn on a line of credit. | D14: Individual franchise unit specific
B15: Estimated Distributions | C15: Amounts of money taken out of the business by the owners or partners. After the business earns money and pays its bills, the leftover profits can either be kept in the business or distributed to the owners. | D15: Depends on post-tax profitability
... B19: Cash Flow | C19: Refers to the money coming into and going out of the business. | D19: N/A

Sheet Input Assumptions
B1: Assumptions Input
B4: Company Name: | E4: ABC Company
E6: Explanation | K6: Click to Navigate
B7: Start of Business Operations: | C7: Explanation | D7: 45505 | E7: Accounts Receivable Days: | H7: 30 | K7: Summary Financials
B8: Financial Year End: | D8: =EOMONTH(Start_Date,11) -> 45869 | E8: Accounts Payable Days - Materials: | H8: 60 | K8: P&L Statement
B9: Gross Sales/Average Unit Volume (AUV): | C9: Explanation | D9: 526994 | E9: Inventory Days: | H9: 60 | K9: Balance Sheet
B10: Time to Reach AUV (months): | C10: Explanation | D10: 18 | E10: Fixed Assets Depreciation Rate: | H10: 0.25 | K10: Cash Flow Statement
B11: Starting Month AUV % | C11: Explanation | D11: 0.3 | E11: Tax Payment Delay (in months): | H11: 9 | K11: Returns on Invested Capital
B12: Corporation Tax: | C12: Explanation | D12: 0.21 | K12: Valuation
B13: EBITDA Multiple | C13: Explanation | D13: 5 | K13: Model
E17: =IF(MONTH(Fin_Year_End)=12,YEAR(Start_Date)+B$18,YEAR(Start_Date)+B$18&"-"&YEAR(Start_Date)+E$18) -> 2024-2025 | F17: =IF(MONTH(Fin_Year_End)=12,YEAR(Start_Date)+E$18,YEAR(Start_Date)+E$18&"-"&YEAR(Start_Date)+F$18) -> 2025-2026 | G17: =IF(MONTH(Fin_Year_End)=12,YEAR(Start_Date)+F$18,YEAR(Start_Date)+F$18&"-"&YEAR(Start_Date)+G$18) -> 2026-2027 | H17: =IF(MONTH(Fin_Year_End)=12,YEAR(Start_Date)+G$18,YEAR(Start_Date)+G$18&"-"&YEAR(Start_Date)+H$18) -> 2027-2028 | I17: =IF(MONTH(Fin_Year_End)=12,YEAR(Start_Date)+H$18,YEAR(Start_Date)+H$18&"-"&YEAR(Start_Date)+I$18) -> 2028-2029
E18: 1 | F18: =E18+1 -> 2 | G18: =F18+1 -> 3 | H18: =G18+1 -> 4 | I18: =H18+1 -> 5
E19: Year 1 | F19: Year 2 | G19: Year 3 | H19: Year 4 | I19: Year 5
B21: Revenue | C21: Explanation | D21: Annual Growth Rate (% of Revenue) | E21: 0.13 | F21: 0.13 | G21: 0.1 | H21: 0.08 | I21: 0.08
B24: Franchise fees | C24: Explanation | D24: Royalty Fee (% of Revenue) | E24: 0.07 | F24: 0.07 | G24: 0.07 | H24: 0.07 | I24: 0.07
D25: Marketing Fee /Ad Fund (% of Revenue) | E25: 0 | F25: 0 | G25: 0 | H25: 0 | I25: 0
B28: Operating Expenses | C28: Explanation | D28: Materials COGs (% of Revenue) | E28: 0.32 | F28: 0.32 | G28: 0.32 | H28: 0.32 | I28: 0.32
C29: Explanation | D29: Direct Labor Cost (% of Revenue) | E29: 0.15 | F29: 0.15 | G29: 0.15 | H29: 0.15 | I29: 0.15
C30: Explanation | D30: Facilities ($) | E30: 40000 | F30: =E30*1.03 -> 41200 | G30: =F30*1.03 -> 42436 | H30: =G30*1.03 -> 43709.08 | I30: =H30*1.03 -> 45020.352
C31: Explanation | D31: Marketing (% of Revenue) | E31: 0.05 | F31: 0.04 | G31: 0.02 | H31: 0.02 | I31: 0.02
C32: Explanation | D32: Management & Admin Salaries ($) | E32: 0 | F32: ='P&L Statement'!F20/3 -> 78437.593 | G32: ='P&L Statement'!G20/3 -> 91017.433 | H32: ='P&L Statement'!H20/3 -> 99458.128 | I32: ='P&L Statement'!I20/3 -> 107713.1
C33: Explanation | D33: Payroll Taxes & Benefits (% of Direct Labor Cost and Management & Admin Salaries) | E33: 0.2 | F33: 0.2 | G33: 0.2 | H33: 0.2 | I33: 0.2
C34: Explanation | D34: Other Operating Expenses (% of Revenue) | E34: 0.03 | F34: 0.03 | G34: 0.03 | H34: 0.03 | I34: 0.03
B37: P&L Calculations | D37: Target Pre-tax Profit (% of Revenue) | E37: 0.15 | F37: 0.15 | G37: 0.15 | H37: 0.15 | I37: 0.15
C38: Explanation | D38: Shareholder salary adjustment (+=underpayed) | E38: 55000 | F38: 0 | G38: 0 | H38: 0 | I38: 0
B41: Total Investment Spending | C41: Explanation | D41: Total investment required | E41: =+AVERAGE(151350,447150) -> 299250
D42: CapEx investments | E42: =32000+AVERAGE(9650,22000)+22500+2500+AVERAGE(5000,30000)+AVERAGE(50000,125000) -> 177825
D43: Non-CapEx investments | E43: =E41-E42-E44 -> 93675
D44: Working Capital / Additional Funds | E44: =+AVERAGE(18500,37000) -> 27750
D45: Check - total investment required | E45: =E41-SUM(E42:E44) -> 0 | F45: =F41-SUM(F42:F44) -> 0 | G45: =G41-SUM(G42:G44) -> 0 | H45: =H41-SUM(H42:H44) -> 0 | I45: =I41-SUM(I42:I44) -> 0
B48: Financing | C48: Explanation | D48: Equity / Cash Injection | E48: =E41*0.2 -> 59850
D49: Debt | E49: =E41*0.8 -> 239400
D50: Debt Term (Months) | E50: =12*12 -> 144
D51: Debt Interest Rate | E51: 0.105
D52: Check - additional financing above total investment required | E52: =SUM(E48:E49)-E41 -> 0
B55: Distributions | C55: Explanation | D55: Estimated Distributions from the Company | E55: 0 | F55: 0 | G55: 0 | H55: 0 | I55: 0

Sheet Summary Financials
B1: Year | E1: ='Input Assumptions'!E$18 -> 1 | F1: ='Input Assumptions'!F$18 -> 2 | G1: ='Input Assumptions'!G$18 -> 3 | H1: ='Input Assumptions'!H$18 -> 4 | I1: ='Input Assumptions'!I$18 -> 5
E2: =Model!E$13 -> 2024-2025 | F2: =Model!F$13 -> 2025-2026 | G2: =Model!G$13 -> 2026-2027 | H2: =Model!H$13 -> 2027-2028 | I2: =Model!I$13 -> 2028-2029
E3: =Model!E$12 -> Year 1 | F3: =Model!F$12 -> Year 2 | G3: =Model!G$12 -> Year 3 | H3: =Model!H$12 -> Year 4 | I3: =Model!I$12 -> Year 5
B5: Summary Financials | E5: =Curr_USD -> $ USD | F5: =Curr_USD -> $ USD | G5: =Curr_USD -> $ USD | H5: =Curr_USD -> $ USD | I5: =Curr_USD -> $ USD
B7: Ramp up to AUV % then Average Growth Rate | E7: =Model!E$24 -> 0.54953704 | F7: =Model!F$24 -> 0.51638889 | G7: =Model!G$24 -> 0.1 | H7: =Model!H$24 -> 0.08 | I7: =Model!I$24 -> 0.08
B9: Revenue | E9: =Model!E$26 -> 289602.72 | F9: =Model!F$26 -> 511549.52 | G9: =Model!G$26 -> 593591.95 | H9: =Model!H$26 -> 648639.97 | I9: =Model!I$26 -> 702476.76
B11: Cost of Sales | E11: =Model!E$35 -> -92672.871 | F11: =Model!F$35 -> -163695.85 | G11: =Model!G$35 -> -189949.43 | H11: =Model!H$35 -> -207564.79 | I11: =Model!I$35 -> -224792.56
B12: COGS (as % of revenue) | E12: {=INDEX(Materials_COGs,E$1)} -> 0.32 | F12: {=INDEX(Materials_COGs,F$1)} -> 0.32 | G12: {=INDEX(Materials_COGs,G$1)} -> 0.32 | H12: {=INDEX(Materials_COGs,H$1)} -> 0.32 | I12: {=INDEX(Materials_COGs,I$1)} -> 0.32
B14: Gross Profit | E14: =E9+E11 -> 196929.85 | F14: =F9+F11 -> 347853.68 | G14: =G9+G11 -> 403642.53 | H14: =H9+H11 -> 441075.18 | I14: =I9+I11 -> 477684.2
B15: Gross Profit % | E15: =IFERROR(E14/E$9,0) -> 0.68 | F15: =IFERROR(F14/F$9,0) -> 0.68 | G15: =IFERROR(G14/G$9,0) -> 0.68 | H15: =IFERROR(H14/H$9,0) -> 0.68 | I15: =IFERROR(I14/I$9,0) -> 0.68
B17: Direct Labor | E17: =Model!E$42 -> -43440.408 | F17: =Model!F$42 -> -76732.428 | G17: =Model!G$42 -> -89038.793 | H17: =Model!H$42 -> -97295.995 | I17: =Model!I$42 -> -105371.51
B18: Direct Labor (as % of revenue) | E18: {=INDEX(Direct_Labor_Cost,E$1)} -> 0.15 | F18: {=INDEX(Direct_Labor_Cost,F$1)} -> 0.15 | G18: {=INDEX(Direct_Labor_Cost,G$1)} -> 0.15 | H18: {=INDEX(Direct_Labor_Cost,H$1)} -> 0.15 | I18: {=INDEX(Direct_Labor_Cost,I$1)} -> 0.15
B19: Contribution Margin (as % of revenue) | E19: =IFERROR((E14+E17)/E$9,0) -> 0.53 | F19: =IFERROR((F14+F17)/F$9,0) -> 0.53 | G19: =IFERROR((G14+G17)/G$9,0) -> 0.53 | H19: =IFERROR((H14+H17)/H$9,0) -> 0.53 | I19: =IFERROR((I14+I17)/I$9,0) -> 0.53
B21: Total Operating Expenses | E21: =Model!E$67 -> -165531.3 | F21: =Model!F$67 -> -186480.06 | G21: =Model!G$67 -> -199144.28 | H21: =Model!H$67 -> -214950.03 | I21: =Model!I$67 -> -230474.22
B22: Total Operating Expenses (as % of revenue) | E22: =IFERROR(E$21/E$9,0) -> -0.57158061 | F22: =IFERROR(F$21/F$9,0) -> -0.36453961 | G22: =IFERROR(G$21/G$9,0) -> -0.33549019 | H22: =IFERROR(H$21/H$9,0) -> -0.33138573 | I22: =IFERROR(I$21/I$9,0) -> -0.32808803
B24: EBITDA | E24: =Model!E70 -> -32314.048 | F24: =Model!F70 -> 48832.716 | G24: =Model!G70 -> 73908.023 | H24: =Model!H70 -> 83424.353 | I24: =Model!I70 -> 92665.093
B25: EBITDA (as % of revenue) | E25: =Model!E71 -> -0.11158061 | F25: =Model!F71 -> 0.095460388 | G25: =Model!G71 -> 0.12450981 | H25: =Model!H71 -> 0.12861427 | I25: =Model!I71 -> 0.13191197
B27: =Model!B73 -> Depreciation & Amortization | E27: =Model!E73 -> -44456.25 | F27: =Model!F73 -> -44456.25 | G27: =Model!G73 -> -44456.25 | H27: =Model!H73 -> -44456.25 | I27: =Model!I73 -> 0
B28: =Model!B76 -> Interest | E28: =Model!E76 -> -24089.625 | F28: =Model!F76 -> -21994.875 | G28: =Model!G76 -> -19900.125 | H28: =Model!H76 -> -17805.375 | I28: =Model!I76 -> -15710.625
B30: =Model!B78 -> Net Profit Before Tax | C30: Explanation | E30: =Model!E78 -> -100859.92 | F30: =Model!F78 -> -17618.409 | G30: =Model!G78 -> 9551.648 | H30: =Model!H78 -> 21162.728 | I30: =Model!I78 -> 76954.468
B31: =Model!B79 -> Net PBT(as % of revenue) | E31: =Model!E79 -> -0.34826994 | F31: =Model!F79 -> -0.034441258 | G31: =Model!G79 -> 0.016091269 | H31: =Model!H79 -> 0.032626309 | I31: =Model!I79 -> 0.10954735
B33: Adj. Net Profit Before Tax | C33: Explanation | E33: =E30-'Input Assumptions'!E38 -> -155859.92 | F33: =F30-'Input Assumptions'!F38 -> -17618.409 | G33: =G30-'Input Assumptions'!G38 -> 9551.648 | H33: =H30-'Input Assumptions'!H38 -> 21162.728 | I33: =I30-'Input Assumptions'!I38 -> 76954.468
B34: Adj. Net PBT (as % of revenue) | E34: =E33/E9 -> -0.53818528 | F34: =F33/F9 -> -0.034441258 | G34: =G33/G9 -> 0.016091269 | H34: =H33/H9 -> 0.032626309 | I34: =I33/I9 -> 0.10954735
B38: Labor Efficiency | C38: Explanation
B40: Direct LER | E40: ='P&L Statement'!E18 -> 4.0666667 | F40: ='P&L Statement'!F18 -> 4.0666667 | G40: ='P&L Statement'!G18 -> 4.0666667 | H40: ='P&L Statement'!H18 -> 4.0666667 | I40: ='P&L Statement'!I18 -> 4.0666667
B42: Admin LER - Forecasted | E42: ='P&L Statement'!E32 | F42: ='P&L Statement'!F32 -> 3 | G42: ='P&L Statement'!G32 -> 3 | H42: ='P&L Statement'!H32 -> 3 | I42: ='P&L Statement'!I32 -> 3
B43: Admin LER - Benchmark | E43: 2 | F43: 2 | G43: 2 | H43: 2 | I43: 2
B44: Difference | E44: =IFERROR(E42-E43,"") -> -2 | F44: =IFERROR(F42-F43,"") -> 1 | G44: =IFERROR(G42-G43,"") -> 1 | H44: =IFERROR(H42-H43,"") -> 1 | I44: =IFERROR(I42-I43,"") -> 1
B46: Adj Total LER - Actual | E46: ='P&L Statement'!E60 -> 1.7945645 | F46: ='P&L Statement'!F60 -> 2.010989 | G46: ='P&L Statement'!G60 -> 2.010989 | H46: ='P&L Statement'!H60 -> 2.010989 | I46: ='P&L Statement'!I60 -> 2.010989
B47: Adj Total LER - Benchmark | E47: 2 | F47: 2 | G47: 2 | H47: 2 | I47: 2
B48: Difference | E48: =IFERROR(E46-E47,"") -> -0.20543552 | F48: =IFERROR(F46-F47,"") -> 0.010989011 | G48: =IFERROR(G46-G47,"") -> 0.010989011 | H48: =IFERROR(H46-H47,"") -> 0.010989011 | I48: =IFERROR(I46-I47,"") -> 0.010989011
B50: Salary Cap | E50: ='P&L Statement'!E56 -> 61360.952 | F50: ='P&L Statement'!F56 -> 127270.31 | G50: ='P&L Statement'!G56 -> 164925.46 | H50: ='P&L Statement'!H56 -> 182882.48 | I50: ='P&L Statement'!I56 -> 200378.2
B51: (Over)/Under cap Using Adj Total Wages | E51: ='P&L Statement'!E57 -> -37079.456 | F51: ='P&L Statement'!F57 -> -27899.712 | G51: ='P&L Statement'!G57 -> -15130.77 | H51: ='P&L Statement'!H57 -> -13871.642 | I51: ='P&L Statement'!I57 -> -12706.421
B54: Balance Sheet
B56: Assets | E56: =Model!E100 -> 199293.17 | F56: =Model!F100 -> 169887.92 | G56: =Model!G100 -> 162527.95 | H56: =Model!H100 -> 166401.19 | I56: =Model!I100 -> 226287
B57: (of which Cash) | E57: =Model!E92 -> 12088.443 | F57: =Model!F92 -> 6064.8014 | G57: =Model!G92 -> 35316.959 | H57: =Model!H92 -> 76777.854 | I57: =Model!I92 -> 129224.97
B59: Liabilities | E59: =Model!E110 -> 240303.1 | F59: =Model!F110 -> 228516.25 | G59: =Model!G110 -> 211604.63 | H59: =Model!H110 -> 194315.15 | I59: =Model!I110 -> 177246.49
B61: Total Net Assets | E61: =Model!E112 -> -41009.923 | F61: =Model!F112 -> -58628.332 | G61: =Model!G112 -> -49076.683 | H61: =Model!H112 -> -27913.955 | I61: =Model!I112 -> 49040.513
B63: Total Liabilities and Equity | E63: =Model!E116 -> -41009.923 | F63: =Model!F116 -> -58628.332 | G63: =Model!G116 -> -49076.683 | H63: =Model!H116 -> -27913.955 | I63: =Model!I116 -> 49040.513
B64: (of which Retained Earnings) | E64: =Model!E115 -> -100859.92 | F64: =Model!F115 -> -118478.33 | G64: =Model!G115 -> -108926.68 | H64: =Model!H115 -> -87763.955 | I64: =Model!I115 -> -10809.487
...

Sheet P&L Statement
B1: =Company_Name -> ABC Company | E1: ='Input Assumptions'!E$18 -> 1 | F1: ='Input Assumptions'!F$18 -> 2 | G1: ='Input Assumptions'!G$18 -> 3 | H1: ='Input Assumptions'!H$18 -> 4 | I1: ='Input Assumptions'!I$18 -> 5 | K1: =IF(K$4<Fin_Year_End,1,IF(MONTH(K$4)=MONTH(Fin_Year_End)+1,MIN(J1+1,5),J1)) -> 1 | L1: =IF(L$4<Fin_Year_End,1,IF(MONTH(L$4)=MONTH(Fin_Year_End)+1,MIN(K1+1,5),K1)) -> 1 | M1: =IF(M$4<Fin_Year_End,1,IF(MONTH(M$4)=MONTH(Fin_Year_End)+1,MIN(L1+1,5),L1)) -> 1 | N1: =IF(N$4<Fin_Year_End,1,IF(MONTH(N$4)=MONTH(Fin_Year_End)+1,MIN(M1+1,5),M1)) -> 1 | O1: =IF(O$4<Fin_Year_End,1,IF(MONTH(O$4)=MONTH(Fin_Year_End)+1,MIN(N1+1,5),N1)) -> 1 | P1: =IF(P$4<Fin_Year_End,1,IF(MONTH(P$4)=MONTH(Fin_Year_End)+1,MIN(O1+1,5),O1)) -> 1 | Q1: =IF(Q$4<Fin_Year_End,1,IF(MONTH(Q$4)=MONTH(Fin_Year_End)+1,MIN(P1+1,5),P1)) -> 1 | R1: =IF(R$4<Fin_Year_End,1,IF(MONTH(R$4)=MONTH(Fin_Year_End)+1,MIN(Q1+1,5),Q1)) -> 1 | ... BR1: =IF(BR$4<Fin_Year_End,1,IF(MONTH(BR$4)=MONTH(Fin_Year_End)+1,MIN(BQ1+1,5),BQ1)) -> 5
B2: Profit & Loss
E3: ='Input Assumptions'!E$17 -> 2024-2025 | F3: ='Input Assumptions'!F$17 -> 2025-2026 | G3: ='Input Assumptions'!G$17 -> 2026-2027 | H3: ='Input Assumptions'!H$17 -> 2027-2028 | I3: ='Input Assumptions'!I$17 -> 2028-2029
E4: =Model!E$12 -> Year 1 | F4: =Model!F$12 -> Year 2 | G4: =Model!G$12 -> Year 3 | H4: =Model!H$12 -> Year 4 | I4: =Model!I$12 -> Year 5 | K4: =EOMONTH(Start_Date,-1)+1 -> 45505 | L4: =EOMONTH(K4,0)+1 -> 45536 | M4: =EOMONTH(L4,0)+1 -> 45566 | N4: =EOMONTH(M4,0)+1 -> 45597 | O4: =EOMONTH(N4,0)+1 -> 45627 | P4: =EOMONTH(O4,0)+1 -> 45658 | Q4: =EOMONTH(P4,0)+1 -> 45689 | R4: =EOMONTH(Q4,0)+1 -> 45717 | S4: =EOMONTH(R4,0)+1 -> 45748 | ... BR4: =EOMONTH(BQ4,0)+1 -> 47300
B5: Revenue Growth | E5: ='Input Assumptions'!E$21 -> 0.13 | F5: ='Input Assumptions'!F$21 -> 0.13 | G5: ='Input Assumptions'!G$21 -> 0.1 | H5: ='Input Assumptions'!H$21 -> 0.08 | I5: ='Input Assumptions'!I$21 -> 0.08
B6: Revenue | E6: =SUMIFS($K6:$BR6,$K$1:$BR$1,E$1) -> 289602.72 | F6: =SUMIFS($K6:$BR6,$K$1:$BR$1,F$1) -> 511549.52 | G6: =SUMIFS($K6:$BR6,$K$1:$BR$1,G$1) -> 593591.95 | H6: =SUMIFS($K6:$BR6,$K$1:$BR$1,H$1) -> 648639.97 | I6: =SUMIFS($K6:$BR6,$K$1:$BR$1,I$1) -> 702476.76 | K6: =Model!K$26 -> 13174.85 | L6: =Model!L$26 -> 16590.552 | M6: =Model!M$26 -> 18298.403 | N6: =Model!N$26 -> 20006.254 | O6: =Model!O$26 -> 21714.105 | P6: =Model!P$26 -> 23421.956 | Q6: =Model!Q$26 -> 25129.806 | R6: =Model!R$26 -> 26837.657 | ... BR6: =Model!BR$26 -> 60702.666
B8: Cost of Goods Sold:
B9: Materials | E9: =SUMIFS($K9:$BR9,$K$1:$BR$1,E$1) -> 92672.871 | F9: =SUMIFS($K9:$BR9,$K$1:$BR$1,F$1) -> 163695.85 | G9: =SUMIFS($K9:$BR9,$K$1:$BR$1,G$1) -> 189949.43 | H9: =SUMIFS($K9:$BR9,$K$1:$BR$1,H$1) -> 207564.79 | I9: =SUMIFS($K9:$BR9,$K$1:$BR$1,I$1) -> 224792.56 | K9: =-Model!K35 -> 4215.952 | L9: =-Model!L35 -> 5308.9766 | M9: =-Model!M35 -> 5855.4889 | N9: =-Model!N35 -> 6402.0012 | O9: =-Model!O35 -> 6948.5135 | P9: =-Model!P35 -> 7495.0258 | Q9: =-Model!Q35 -> 8041.5381 | R9: =-Model!R35 -> 8588.0504 | ... BR9: =-Model!BR35 -> 19424.853
B10: Royalties | E10: =SUMIFS($K10:$BR10,$K$1:$BR$1,E$1) -> 20272.19 | F10: =SUMIFS($K10:$BR10,$K$1:$BR$1,F$1) -> 35808.467 | G10: =SUMIFS($K10:$BR10,$K$1:$BR$1,G$1) -> 41551.437 | H10: =SUMIFS($K10:$BR10,$K$1:$BR$1,H$1) -> 45404.798 | I10: =SUMIFS($K10:$BR10,$K$1:$BR$1,I$1) -> 49173.373 | K10: =-Model!K29 -> 922.2395 | L10: =-Model!L29 -> 1161.3386 | M10: =-Model!M29 -> 1280.8882 | N10: =-Model!N29 -> 1400.4378 | O10: =-Model!O29 -> 1519.9873 | P10: =-Model!P29 -> 1639.5369 | Q10: =-Model!Q29 -> 1759.0865 | R10: =-Model!R29 -> 1878.636 | ... BR10: =-Model!BR29 -> 4249.1866
B11: Ad Fund / Brand Fund | E11: =SUMIFS($K11:$BR11,$K$1:$BR$1,E$1) -> 0 | F11: =SUMIFS($K11:$BR11,$K$1:$BR$1,F$1) -> 0 | G11: =SUMIFS($K11:$BR11,$K$1:$BR$1,G$1) -> 0 | H11: =SUMIFS($K11:$BR11,$K$1:$BR$1,H$1) -> 0 | I11: =SUMIFS($K11:$BR11,$K$1:$BR$1,I$1) -> 0 | K11: =-Model!K32 -> 0 | L11: =-Model!L32 -> 0 | M11: =-Model!M32 -> 0 | N11: =-Model!N32 -> 0 | O11: =-Model!O32 -> 0 | P11: =-Model!P32 -> 0 | Q11: =-Model!Q32 -> 0 | R11: =-Model!R32 -> 0 | ... BR11: =-Model!BR32 -> 0
B12: Total Cost of Goods Sold | E12: =SUM(E9:E11) -> 112945.06 | F12: =SUM(F9:F11) -> 199504.31 | G12: =SUM(G9:G11) -> 231500.86 | H12: =SUM(H9:H11) -> 252969.59 | I12: =SUM(I9:I11) -> 273965.94 | K12: =SUM(K9:K11) -> 5138.1915 | L12: =SUM(L9:L11) -> 6470.3152 | M12: =SUM(M9:M11) -> 7136.3771 | N12: =SUM(N9:N11) -> 7802.4389 | O12: =SUM(O9:O11) -> 8468.5008 | P12: =SUM(P9:P11) -> 9134.5627 | Q12: =SUM(Q9:Q11) -> 9800.6245 | R12: =SUM(R9:R11) -> 10466.686 | ... BR12: =SUM(BR9:BR11) -> 23674.04
B14: Gross Profit | E14: =+E6-E12 -> 176657.66 | F14: =+F6-F12 -> 312045.21 | G14: =+G6-G12 -> 362091.09 | H14: =+H6-H12 -> 395670.38 | I14: =+I6-I12 -> 428510.83 | K14: =+K6-K12 -> 8036.6585 | L14: =+L6-L12 -> 10120.237 | M14: =+M6-M12 -> 11162.026 | N14: =+N6-N12 -> 12203.815 | O14: =+O6-O12 -> 13245.604 | P14: =+P6-P12 -> 14287.393 | Q14: =+Q6-Q12 -> 15329.182 | R14: =+R6-R12 -> 16370.971 | ... BR14: =+BR6-BR12 -> 37028.626
B15: Gross Profit as % of Revenue | E15: =IFERROR(E14/E6,0) -> 0.61 | F15: =IFERROR(F14/F6,0) -> 0.61 | G15: =IFERROR(G14/G6,0) -> 0.61 | H15: =IFERROR(H14/H6,0) -> 0.61 | I15: =IFERROR(I14/I6,0) -> 0.61 | K15: =IFERROR(K14/K6,0) -> 0.61 | L15: =IFERROR(L14/L6,0) -> 0.61 | M15: =IFERROR(M14/M6,0) -> 0.61 | N15: =IFERROR(N14/N6,0) -> 0.61 | O15: =IFERROR(O14/O6,0) -> 0.61 | P15: =IFERROR(P14/P6,0) -> 0.61 | Q15: =IFERROR(Q14/Q6,0) -> 0.61 | R15: =IFERROR(R14/R6,0) -> 0.61 | ... BR15: =IFERROR(BR14/BR6,0) -> 0.61
B17: Direct Labor | E17: =SUMIFS($K17:$BR17,$K$1:$BR$1,E$1) -> 43440.408 | F17: =SUMIFS($K17:$BR17,$K$1:$BR$1,F$1) -> 76732.428 | G17: =SUMIFS($K17:$BR17,$K$1:$BR$1,G$1) -> 89038.793 | H17: =SUMIFS($K17:$BR17,$K$1:$BR$1,H$1) -> 97295.995 | I17: =SUMIFS($K17:$BR17,$K$1:$BR$1,I$1) -> 105371.51 | K17: =-Model!K42 -> 1976.2275 | L17: =-Model!L42 -> 2488.5828 | M17: =-Model!M42 -> 2744.7604 | N17: =-Model!N42 -> 3000.9381 | O17: =-Model!O42 -> 3257.1157 | P17: =-Model!P42 -> 3513.2933 | Q17: =-Model!Q42 -> 3769.471 | R17: =-Model!R42 -> 4025.6486 | ... BR17: =-Model!BR42 -> 9105.3998
B18: Direct LER | E18: =IFERROR(E14/E17,"") -> 4.0666667 | F18: =IFERROR(F14/F17,"") -> 4.0666667 | G18: =IFERROR(G14/G17,"") -> 4.0666667 | H18: =IFERROR(H14/H17,"") -> 4.0666667 | I18: =IFERROR(I14/I17,"") -> 4.0666667 | K18: =IFERROR(K14/K17,"") -> 4.0666667 | L18: =IFERROR(L14/L17,"") -> 4.0666667 | M18: =IFERROR(M14/M17,"") -> 4.0666667 | N18: =IFERROR(N14/N17,"") -> 4.0666667 | O18: =IFERROR(O14/O17,"") -> 4.0666667 | P18: =IFERROR(P14/P17,"") -> 4.0666667 | Q18: =IFERROR(Q14/Q17,"") -> 4.0666667 | R18: =IFERROR(R14/R17,"") -> 4.0666667 | ... BR18: =IFERROR(BR14/BR17,"") -> 4.0666667
B20: Contribution Margin | E20: =E14-E17 -> 133217.25 | F20: =F14-F17 -> 235312.78 | G20: =G14-G17 -> 273052.3 | H20: =H14-H17 -> 298374.38 | I20: =I14-I17 -> 323139.31 | K20: =K14-K17 -> 6060.431 | L20: =L14-L17 -> 7631.6539 | M20: =M14-M17 -> 8417.2653 | N20: =N14-N17 -> 9202.8767 | O20: =O14-O17 -> 9988.4881 | P20: =P14-P17 -> 10774.1 | Q20: =Q14-Q17 -> 11559.711 | R20: =R14-R17 -> 12345.322 | ... BR20: =BR14-BR17 -> 27923.226
B21: As % of GP | E21: =IFERROR(E20/E14,"") -> 0.75409836 | F21: =IFERROR(F20/F14,"") -> 0.75409836 | G21: =IFERROR(G20/G14,"") -> 0.75409836 | H21: =IFERROR(H20/H14,"") -> 0.75409836 | I21: =IFERROR(I20/I14,"") -> 0.75409836 | K21: =IFERROR(K20/K14,"") -> 0.75409836 | L21: =IFERROR(L20/L14,"") -> 0.75409836 | M21: =IFERROR(M20/M14,"") -> 0.75409836 | N21: =IFERROR(N20/N14,"") -> 0.75409836 | O21: =IFERROR(O20/O14,"") -> 0.75409836 | P21: =IFERROR(P20/P14,"") -> 0.75409836 | Q21: =IFERROR(Q20/Q14,"") -> 0.75409836 | R21: =IFERROR(R20/R14,"") -> 0.75409836 | ... BR21: =IFERROR(BR20/BR14,"") -> 0.75409836
B23: Operating Expenses:
B24: Facilities | E24: =SUMIFS($K24:$BR24,$K$1:$BR$1,E$1) -> 40000 | F24: =SUMIFS($K24:$BR24,$K$1:$BR$1,F$1) -> 41200 | G24: =SUMIFS($K24:$BR24,$K$1:$BR$1,G$1) -> 42436 | H24: =SUMIFS($K24:$BR24,$K$1:$BR$1,H$1) -> 43709.08 | I24: =SUMIFS($K24:$BR24,$K$1:$BR$1,I$1) -> 45020.352 | K24: =-Model!K54 -> 3333.3333 | L24: =-Model!L54 -> 3333.3333 | M24: =-Model!M54 -> 3333.3333 | N24: =-Model!N54 -> 3333.3333 | O24: =-Model!O54 -> 3333.3333 | P24: =-Model!P54 -> 3333.3333 | Q24: =-Model!Q54 -> 3333.3333 | R24: =-Model!R54 -> 3333.3333 | ... BR24: =-Model!BR54 -> 3751.696
B25: Marketing | E25: =SUMIFS($K25:$BR25,$K$1:$BR$1,E$1) -> 14480.136 | F25: =SUMIFS($K25:$BR25,$K$1:$BR$1,F$1) -> 20461.981 | G25: =SUMIFS($K25:$BR25,$K$1:$BR$1,G$1) -> 11871.839 | H25: =SUMIFS($K25:$BR25,$K$1:$BR$1,H$1) -> 12972.799 | I25: =SUMIFS($K25:$BR25,$K$1:$BR$1,I$1) -> 14049.535 | K25: =-Model!K58 -> 658.7425 | L25: =-Model!L58 -> 829.52759 | M25: =-Model!M58 -> 914.92014 | N25: =-Model!N58 -> 1000.3127 | O25: =-Model!O58 -> 1085.7052 | P25: =-Model!P58 -> 1171.0978 | Q25: =-Model!Q58 -> 1256.4903 | R25: =-Model!R58 -> 1341.8829 | ... BR25: =-Model!BR58 -> 1214.0533
B26: Labor - (Management and Admin) | E26: =SUMIFS($K26:$BR26,$K$1:$BR$1,E$1) -> 0 | F26: =SUMIFS($K26:$BR26,$K$1:$BR$1,F$1) -> 78437.593 | G26: =SUMIFS($K26:$BR26,$K$1:$BR$1,G$1) -> 91017.433 | H26: =SUMIFS($K26:$BR26,$K$1:$BR$1,H$1) -> 99458.128 | I26: =SUMIFS($K26:$BR26,$K$1:$BR$1,I$1) -> 107713.1 | K26: =-Model!K48 -> 0 | L26: =-Model!L48 -> 0 | M26: =-Model!M48 -> 0 | N26: =-Model!N48 -> 0 | O26: =-Model!O48 -> 0 | P26: =-Model!P48 -> 0 | Q26: =-Model!Q48 -> 0 | R26: =-Model!R48 -> 0 | ... BR26: =-Model!BR48 -> 8976.092
B27: Payroll Taxes & Benefits | E27: =SUMIFS($K27:$BR27,$K$1:$BR$1,E$1) -> 8688.0816 | F27: =SUMIFS($K27:$BR27,$K$1:$BR$1,F$1) -> 31034.004 | G27: =SUMIFS($K27:$BR27,$K$1:$BR$1,G$1) -> 36011.245 | H27: =SUMIFS($K27:$BR27,$K$1:$BR$1,H$1) -> 39350.825 | I27: =SUMIFS($K27:$BR27,$K$1:$BR$1,I$1) -> 42616.924 | K27: =-Model!K50 -> 395.2455 | L27: =-Model!L50 -> 497.71656 | M27: =-Model!M50 -> 548.95208 | N27: =-Model!N50 -> 600.18761 | O27: =-Model!O50 -> 651.42314 | P27: =-Model!P50 -> 702.65867 | Q27: =-Model!Q50 -> 753.89419 | R27: =-Model!R50 -> 805.12972 | ... BR27: =-Model!BR50 -> 3616.2984
B28: Other Operating Expenses | E28: =SUMIFS($K28:$BR28,$K$1:$BR$1,E$1) -> 8688.0816 | F28: =SUMIFS($K28:$BR28,$K$1:$BR$1,F$1) -> 15346.486 | G28: =SUMIFS($K28:$BR28,$K$1:$BR$1,G$1) -> 17807.759 | H28: =SUMIFS($K28:$BR28,$K$1:$BR$1,H$1) -> 19459.199 | I28: =SUMIFS($K28:$BR28,$K$1:$BR$1,I$1) -> 21074.303 | K28: =-Model!K62 -> 395.2455 | L28: =-Model!L62 -> 497.71656 | M28: =-Model!M62 -> 548.95208 | N28: =-Model!N62 -> 600.18761 | O28: =-Model!O62 -> 651.42314 | P28: =-Model!P62 -> 702.65867 | Q28: =-Model!Q62 -> 753.89419 | R28: =-Model!R62 -> 805.12972 | ... BR28: =-Model!BR62 -> 1821.08
B29: ='Input Assumptions'!D43 -> Non-CapEx investments | E29: =SUMIFS($K29:$BR29,$K$1:$BR$1,E$1) -> 93675 | F29: =SUMIFS($K29:$BR29,$K$1:$BR$1,F$1) -> 0 | G29: =SUMIFS($K29:$BR29,$K$1:$BR$1,G$1) -> 0 | H29: =SUMIFS($K29:$BR29,$K$1:$BR$1,H$1) -> 0 | I29: =SUMIFS($K29:$BR29,$K$1:$BR$1,I$1) -> 0 | K29: =-Model!K64 -> 7806.25 | L29: =-Model!L64 -> 7806.25 | M29: =-Model!M64 -> 7806.25 | N29: =-Model!N64 -> 7806.25 | O29: =-Model!O64 -> 7806.25 | P29: =-Model!P64 -> 7806.25 | Q29: =-Model!Q64 -> 7806.25 | R29: =-Model!R64 -> 7806.25 | ... BR29: =-Model!BR64 -> 0
B30: Total operating expenses | E30: =SUM(E24:E29) -> 165531.3 | F30: =SUM(F24:F29) -> 186480.06 | G30: =SUM(G24:G29) -> 199144.28 | H30: =SUM(H24:H29) -> 214950.03 | I30: =SUM(I24:I29) -> 230474.22 | K30: =SUM(K24:K29) -> 12588.817 | L30: =SUM(L24:L29) -> 12964.544 | M30: =SUM(M24:M29) -> 13152.408 | N30: =SUM(N24:N29) -> 13340.271 | O30: =SUM(O24:O29) -> 13528.135 | P30: =SUM(P24:P29) -> 13715.998 | Q30: =SUM(Q24:Q29) -> 13903.862 | R30: =SUM(R24:R29) -> 14091.726 | ... BR30: =SUM(BR24:BR29) -> 19379.22
B31: As % of Revenue | E31: =IFERROR(E30/E6,"") -> 0.57158061 | F31: =IFERROR(F30/F6,"") -> 0.36453961 | G31: =IFERROR(G30/G6,"") -> 0.33549019 | H31: =IFERROR(H30/H6,"") -> 0.33138573 | I31: =IFERROR(I30/I6,"") -> 0.32808803 | K31: =IFERROR(K30/K6,"") -> 0.9555188 | L31: =IFERROR(L30/L6,"") -> 0.7814414 | M31: =IFERROR(M30/M6,"") -> 0.71877353 | N31: =IFERROR(N30/N6,"") -> 0.66680506 | O31: =IFERROR(O30/O6,"") -> 0.62301141 | P31: =IFERROR(P30/P6,"") -> 0.58560432 | Q31: =IFERROR(Q30/Q6,"") -> 0.5532817 | R31: =IFERROR(R30/R6,"") -> 0.52507286 | ... BR31: =IFERROR(BR30/BR6,"") -> 0.31924825
B32: Management LER to CM | E32: =IFERROR(E20/E26,"") | F32: =IFERROR(F20/F26,"") -> 3 | G32: =IFERROR(G20/G26,"") -> 3 | H32: =IFERROR(H20/H26,"") -> 3 | I32: =IFERROR(I20/I26,"") -> 3 | K32: =IFERROR(K20/K26,"") | L32: =IFERROR(L20/L26,"") | M32: =IFERROR(M20/M26,"") | N32: =IFERROR(N20/N26,"") | O32: =IFERROR(O20/O26,"") | P32: =IFERROR(P20/P26,"") | Q32: =IFERROR(Q20/Q26,"") | R32: =IFERROR(R20/R26,"") | ... BR32: =IFERROR(BR20/BR26,"") -> 3.1108445
E33: =E34-Model!E70 -> 0 | F33: =F34-Model!F70 -> 1.0186341e-10 | G33: =G34-Model!G70 -> 0 | H33: =H34-Model!H70 -> 0 | I33: =I34-Model!I70 -> 0
B34: Net operating Income | E34: =E20-E30 -> -32314.048 | F34: =F20-F30 -> 48832.716 | G34: =G20-G30 -> 73908.023 | H34: =H20-H30 -> 83424.353 | I34: =I20-I30 -> 92665.093 | K34: =K20-K30 -> -6528.3858 | L34: =L20-L30 -> -5332.8902 | M34: =M20-M30 -> -4735.1424 | N34: =N20-N30 -> -4137.3945 | O34: =O20-O30 -> -3539.6467 | P34: =P20-P30 -> -2941.8989 | Q34: =Q20-Q30 -> -2344.1511 | R34: =R20-R30 -> -1746.4032 | ... BR34: =BR20-BR30 -> 8544.0065
B35: As % of Revenue | E35: =IFERROR(E34/E6,"") -> -0.11158061 | F35: =IFERROR(F34/F6,"") -> 0.095460388 | G35: =IFERROR(G34/G6,"") -> 0.12450981 | H35: =IFERROR(H34/H6,"") -> 0.12861427 | I35: =IFERROR(I34/I6,"") -> 0.13191197 | K35: =IFERROR(K34/K6,"") -> -0.4955188 | L35: =IFERROR(L34/L6,"") -> -0.3214414 | M35: =IFERROR(M34/M6,"") -> -0.25877353 | N35: =IFERROR(N34/N6,"") -> -0.20680506 | O35: =IFERROR(O34/O6,"") -> -0.16301141 | P35: =IFERROR(P34/P6,"") -> -0.12560432 | Q35: =IFERROR(Q34/Q6,"") -> -0.0932817 | R35: =IFERROR(R34/R6,"") -> -0.065072864 | ... BR35: =IFERROR(BR34/BR6,"") -> 0.14075175
B37: Depreciation | E37: =SUMIFS($K37:$BR37,$K$1:$BR$1,E$1) -> -44456.25 | F37: =SUMIFS($K37:$BR37,$K$1:$BR$1,F$1) -> -44456.25 | G37: =SUMIFS($K37:$BR37,$K$1:$BR$1,G$1) -> -44456.25 | H37: =SUMIFS($K37:$BR37,$K$1:$BR$1,H$1) -> -44456.25 | I37: =SUMIFS($K37:$BR37,$K$1:$BR$1,I$1) -> 0 | K37: =Model!K73 -> -3704.6875 | L37: =Model!L73 -> -3704.6875 | M37: =Model!M73 -> -3704.6875 | N37: =Model!N73 -> -3704.6875 | O37: =Model!O73 -> -3704.6875 | P37: =Model!P73 -> -3704.6875 | Q37: =Model!Q73 -> -3704.6875 | R37: =Model!R73 -> -3704.6875 | ... BR37: =Model!BR73 -> 0
B38: Other Income (Expense)
B39: Interest Expense | E39: =SUMIFS($K39:$BR39,$K$1:$BR$1,E$1) -> -24089.625 | F39: =SUMIFS($K39:$BR39,$K$1:$BR$1,F$1) -> -21994.875 | G39: =SUMIFS($K39:$BR39,$K$1:$BR$1,G$1) -> -19900.125 | H39: =SUMIFS($K39:$BR39,$K$1:$BR$1,H$1) -> -17805.375 | I39: =SUMIFS($K39:$BR39,$K$1:$BR$1,I$1) -> -15710.625 | K39: =Model!K76 -> -2087.4766 | L39: =Model!L76 -> -2072.9297 | M39: =Model!M76 -> -2058.3828 | N39: =Model!N76 -> -2043.8359 | O39: =Model!O76 -> -2029.2891 | P39: =Model!P76 -> -2014.7422 | Q39: =Model!Q76 -> -2000.1953 | R39: =Model!R76 -> -1985.6484 | ... BR39: =Model!BR76 -> -1229.2109
B41: Pre-tax Net Income | E41: =E34+E37+E38+E39 -> -100859.92 | F41: =F34+F37+F38+F39 -> -17618.409 | G41: =G34+G37+G38+G39 -> 9551.648 | H41: =H34+H37+H38+H39 -> 21162.728 | I41: =I34+I37+I38+I39 -> 76954.468 | K41: =K34+K37+K38+K39 -> -12320.55 | L41: =L34+L37+L38+L39 -> -11110.507 | M41: =M34+M37+M38+M39 -> -10498.213 | N41: =N34+N37+N38+N39 -> -9885.918 | O41: =O34+O37+O38+O39 -> -9273.6233 | P41: =P34+P37+P38+P39 -> -8661.3286 | Q41: =Q34+Q37+Q38+Q39 -> -8049.0339 | R41: =R34+R37+R38+R39 -> -7436.7392 | ... BR41: =BR34+BR37+BR38+BR39 -> 7314.7956
B42: as a % of Revenue | E42: =E41/E6 -> -0.34826994 | F42: =F41/F6 -> -0.034441258 | G42: =G41/G6 -> 0.016091269 | H42: =H41/H6 -> 0.032626309 | I42: =I41/I6 -> 0.10954735 | K42: =K41/K6 -> -0.93515675 | L42: =L41/L6 -> -0.66968884 | M42: =M41/M6 -> -0.5737229 | N42: =N41/N6 -> -0.49414139 | O42: =O41/O6 -> -0.42707832 | P42: =P41/P6 -> -0.36979528 | Q42: =Q41/Q6 -> -0.32029828 | R42: =R41/R6 -> -0.27710091 | ... BR42: =BR41/BR6 -> 0.12050205
B43: as a % of Gross Profit | E43: =E41/E14 -> -0.57093433 | F43: =F41/F14 -> -0.056461078 | G43: =G41/G14 -> 0.02637913 | H43: =H41/H14 -> 0.053485753 | I43: =I41/I14 -> 0.17958582 | K43: =K41/K14 -> -1.5330439 | L43: =L41/L14 -> -1.0978506 | M43: =M41/M14 -> -0.94052934 | N43: =N41/N14 -> -0.81006785 | O43: =O41/O14 -> -0.70012839 | P43: =P41/P14 -> -0.60622177 | Q43: =Q41/Q14 -> -0.52507915 | R43: =R41/R14 -> -0.45426378 | ... BR43: =BR41/BR14 -> 0.19754434
B45: Target Pre-tax Profit % | E45: =INDEX($K45:$BR45,,MATCH(E$1,$K$1:$BR$1,0)) -> 0.15 | F45: =INDEX($K45:$BR45,,MATCH(F$1,$K$1:$BR$1,0)) -> 0.15 | G45: =INDEX($K45:$BR45,,MATCH(G$1,$K$1:$BR$1,0)) -> 0.15 | H45: =INDEX($K45:$BR45,,MATCH(H$1,$K$1:$BR$1,0)) -> 0.15 | I45: =INDEX($K45:$BR45,,MATCH(I$1,$K$1:$BR$1,0)) -> 0.15 | K45: {=INDEX(Pre_Tax_Profit_Target,K$1)} -> 0.15 | L45: {=INDEX(Pre_Tax_Profit_Target,L$1)} -> 0.15 | M45: {=INDEX(Pre_Tax_Profit_Target,M$1)} -> 0.15 | N45: {=INDEX(Pre_Tax_Profit_Target,N$1)} -> 0.15 | O45: {=INDEX(Pre_Tax_Profit_Target,O$1)} -> 0.15 | P45: {=INDEX(Pre_Tax_Profit_Target,P$1)} -> 0.15 | Q45: {=INDEX(Pre_Tax_Profit_Target,Q$1)} -> 0.15 | R45: {=INDEX(Pre_Tax_Profit_Target,R$1)} -> 0.15 | ... BR45: {=INDEX(Pre_Tax_Profit_Target,BR$1)} -> 0.15
B46: Calculated Pre-tax Profit @15% | E46: =E45*E6 -> 43440.408 | F46: =F45*F6 -> 76732.428 | G46: =G45*G6 -> 89038.793 | H46: =H45*H6 -> 97295.995 | I46: =I45*I6 -> 105371.51 | K46: =K45*K6 -> 1976.2275 | L46: =L45*L6 -> 2488.5828 | M46: =M45*M6 -> 2744.7604 | N46: =N45*N6 -> 3000.9381 | O46: =O45*O6 -> 3257.1157 | P46: =P45*P6 -> 3513.2933 | Q46: =Q45*Q6 -> 3769.471 | R46: =R45*R6 -> 4025.6486 | ... BR46: =BR45*BR6 -> 9105.3998
B47: Above (below) Target | E47: =E41-E46 -> -144300.33 | F47: =F41-F46 -> -94350.837 | G47: =G41-G46 -> -79487.145 | H47: =H41-H46 -> -76133.267 | I47: =I41-I46 -> -28417.046 | K47: =K41-K46 -> -14296.777 | L47: =L41-L46 -> -13599.09 | M47: =M41-M46 -> -13242.973 | N47: =N41-N46 -> -12886.856 | O47: =O41-O46 -> -12530.739 | P47: =P41-P46 -> -12174.622 | Q47: =Q41-Q46 -> -11818.505 | R47: =R41-R46 -> -11462.388 | ... BR47: =BR41-BR46 -> -1790.6042
B49: Shareholder salary adjustment (+=underpayed) | E49: =SUMIFS($K49:$BR49,$K$1:$BR$1,E$1) -> 55000 | F49: =SUMIFS($K49:$BR49,$K$1:$BR$1,F$1) -> 0 | G49: =SUMIFS($K49:$BR49,$K$1:$BR$1,G$1) -> 0 | H49: =SUMIFS($K49:$BR49,$K$1:$BR$1,H$1) -> 0 | I49: =SUMIFS($K49:$BR49,$K$1:$BR$1,I$1) -> 0 | K49: {=IFERROR(INDEX(Shareholder_Salary_Adj,K$1)/12,0)} -> 4583.3333 | L49: {=IFERROR(INDEX(Shareholder_Salary_Adj,L$1)/12,0)} -> 4583.3333 | M49: {=IFERROR(INDEX(Shareholder_Salary_Adj,M$1)/12,0)} -> 4583.3333 | N49: {=IFERROR(INDEX(Shareholder_Salary_Adj,N$1)/12,0)} -> 4583.3333 | O49: {=IFERROR(INDEX(Shareholder_Salary_Adj,O$1)/12,0)} -> 4583.3333 | P49: {=IFERROR(INDEX(Shareholder_Salary_Adj,P$1)/12,0)} -> 4583.3333 | Q49: {=IFERROR(INDEX(Shareholder_Salary_Adj,Q$1)/12,0)} -> 4583.3333 | R49: {=IFERROR(INDEX(Shareholder_Salary_Adj,R$1)/12,0)} -> 4583.3333 | ... BR49: {=IFERROR(INDEX(Shareholder_Salary_Adj,BR$1)/12,0)} -> 0
...

Sheet Balance Sheet
B1: =Company_Name -> ABC Company
B2: Balance Sheet | E2: ='Input Assumptions'!E$18 -> 1 | F2: ='Input Assumptions'!F$18 -> 2 | G2: ='Input Assumptions'!G$18 -> 3 | H2: ='Input Assumptions'!H$18 -> 4 | I2: ='Input Assumptions'!I$18 -> 5 | K2: =IF(K$4<Fin_Year_End,1,IF(MONTH(K$4)=MONTH(Fin_Year_End)+1,MIN(J2+1,5),J2)) -> 1 | L2: =IF(L$4<Fin_Year_End,1,IF(MONTH(L$4)=MONTH(Fin_Year_End)+1,MIN(K2+1,5),K2)) -> 1 | M2: =IF(M$4<Fin_Year_End,1,IF(MONTH(M$4)=MONTH(Fin_Year_End)+1,MIN(L2+1,5),L2)) -> 1 | N2: =IF(N$4<Fin_Year_End,1,IF(MONTH(N$4)=MONTH(Fin_Year_End)+1,MIN(M2+1,5),M2)) -> 1 | O2: =IF(O$4<Fin_Year_End,1,IF(MONTH(O$4)=MONTH(Fin_Year_End)+1,MIN(N2+1,5),N2)) -> 1 | P2: =IF(P$4<Fin_Year_End,1,IF(MONTH(P$4)=MONTH(Fin_Year_End)+1,MIN(O2+1,5),O2)) -> 1 | Q2: =IF(Q$4<Fin_Year_End,1,IF(MONTH(Q$4)=MONTH(Fin_Year_End)+1,MIN(P2+1,5),P2)) -> 1 | R2: =IF(R$4<Fin_Year_End,1,IF(MONTH(R$4)=MONTH(Fin_Year_End)+1,MIN(Q2+1,5),Q2)) -> 1 | ... BR2: =IF(BR$4<Fin_Year_End,1,IF(MONTH(BR$4)=MONTH(Fin_Year_End)+1,MIN(BQ2+1,5),BQ2)) -> 5
E3: ='Input Assumptions'!E$17 -> 2024-2025 | F3: ='Input Assumptions'!F$17 -> 2025-2026 | G3: ='Input Assumptions'!G$17 -> 2026-2027 | H3: ='Input Assumptions'!H$17 -> 2027-2028 | I3: ='Input Assumptions'!I$17 -> 2028-2029
E4: =Model!E$12 -> Year 1 | F4: =Model!F$12 -> Year 2 | G4: =Model!G$12 -> Year 3 | H4: =Model!H$12 -> Year 4 | I4: =Model!I$12 -> Year 5 | K4: =EOMONTH(Start_Date,-1)+1 -> 45505 | L4: =EOMONTH(K4,0)+1 -> 45536 | M4: =EOMONTH(L4,0)+1 -> 45566 | N4: =EOMONTH(M4,0)+1 -> 45597 | O4: =EOMONTH(N4,0)+1 -> 45627 | P4: =EOMONTH(O4,0)+1 -> 45658 | Q4: =EOMONTH(P4,0)+1 -> 45689 | R4: =EOMONTH(Q4,0)+1 -> 45717 | S4: =EOMONTH(R4,0)+1 -> 45748 | ... BR4: =EOMONTH(BQ4,0)+1 -> 47300
B5: ASSETS
B6: Current Assets:
B7: Cash | E7: =INDEX($K7:$BR7,,MATCH(E$2,$K$2:$BR$2,0)+11) -> 12088.443 | F7: =INDEX($K7:$BR7,,MATCH(F$2,$K$2:$BR$2,0)+11) -> 6064.8014 | G7: =INDEX($K7:$BR7,,MATCH(G$2,$K$2:$BR$2,0)+11) -> 35316.959 | H7: =INDEX($K7:$BR7,,MATCH(H$2,$K$2:$BR$2,0)+11) -> 76777.854 | I7: =INDEX($K7:$BR7,,MATCH(I$2,$K$2:$BR$2,0)+11) -> 129224.97 | K7: =Model!K92 -> 98240.291 | L7: =Model!L92 -> 85290.703 | M7: =Model!M92 -> 75696.812 | N7: =Model!N92 -> 65534.673 | O7: =Model!O92 -> 57275.556 | P7: =Model!P92 -> 48983.37 | Q7: =Model!Q92 -> 38697.853 | R7: =Model!R92 -> 34235.882 | ... BR7: =Model!BR92 -> 129224.97
B8: Accounts receivable | E8: =INDEX($K8:$BR8,,MATCH(E$2,$K$2:$BR$2,0)+11) -> 32582.962 | F8: =INDEX($K8:$BR8,,MATCH(F$2,$K$2:$BR$2,0)+11) -> 45337.891 | G8: =INDEX($K8:$BR8,,MATCH(G$2,$K$2:$BR$2,0)+11) -> 50085.361 | H8: =INDEX($K8:$BR8,,MATCH(H$2,$K$2:$BR$2,0)+11) -> 54242.421 | I8: =INDEX($K8:$BR8,,MATCH(I$2,$K$2:$BR$2,0)+11) -> 58744.515 | K8: =Model!K93 -> 12749.855 | L8: =Model!L93 -> 16590.552 | M8: =Model!M93 -> 17708.132 | N8: =Model!N93 -> 20006.254 | O8: =Model!O93 -> 21013.65 | P8: =Model!P93 -> 22666.409 | Q8: =Model!Q93 -> 26924.793 | R8: =Model!R93 -> 25971.927 | ... BR8: =Model!BR93 -> 58744.515
B9: Other Current Assets | E9: =INDEX($K9:$BR9,,MATCH(E$2,$K$2:$BR$2,0)+11) -> 21253.018 | F9: =INDEX($K9:$BR9,,MATCH(F$2,$K$2:$BR$2,0)+11) -> 29572.726 | G9: =INDEX($K9:$BR9,,MATCH(G$2,$K$2:$BR$2,0)+11) -> 32669.377 | H9: =INDEX($K9:$BR9,,MATCH(H$2,$K$2:$BR$2,0)+11) -> 35380.919 | I9: =INDEX($K9:$BR9,,MATCH(I$2,$K$2:$BR$2,0)+11) -> 38317.518 | K9: =Model!K94 -> 8316.3985 | L9: =Model!L94 -> 10472.502 | M9: =Model!M94 -> 11550.553 | N9: =Model!N94 -> 12628.605 | O9: =Model!O94 -> 13706.657 | P9: =Model!P94 -> 14784.708 | Q9: =Model!Q94 -> 15862.76 | R9: =Model!R94 -> 16940.812 | ... BR9: =Model!BR94 -> 38317.518
B11: Total current assets | E11: =SUM(E7:E9) -> 65924.423 | F11: =SUM(F7:F9) -> 80975.419 | G11: =SUM(G7:G9) -> 118071.7 | H11: =SUM(H7:H9) -> 166401.19 | I11: =SUM(I7:I9) -> 226287 | K11: =SUM(K7:K9) -> 119306.54 | L11: =SUM(L7:L9) -> 112353.76 | M11: =SUM(M7:M9) -> 104955.5 | N11: =SUM(N7:N9) -> 98169.532 | O11: =SUM(O7:O9) -> 91995.862 | P11: =SUM(P7:P9) -> 86434.487 | Q11: =SUM(Q7:Q9) -> 81485.406 | R11: =SUM(R7:R9) -> 77148.62 | ... BR11: =SUM(BR7:BR9) -> 226287
B13: Fixed Assets:
B14: Equipment | E14: =INDEX($K14:$BR14,,MATCH(E$2,$K$2:$BR$2,0)+11) -> 177825 | F14: =INDEX($K14:$BR14,,MATCH(F$2,$K$2:$BR$2,0)+11) -> 177825 | G14: =INDEX($K14:$BR14,,MATCH(G$2,$K$2:$BR$2,0)+11) -> 177825 | H14: =INDEX($K14:$BR14,,MATCH(H$2,$K$2:$BR$2,0)+11) -> 177825 | I14: =INDEX($K14:$BR14,,MATCH(I$2,$K$2:$BR$2,0)+11) -> 177825 | K14: =Model!K239+J14 -> 177825 | L14: =Model!L239+K14 -> 177825 | M14: =Model!M239+L14 -> 177825 | N14: =Model!N239+M14 -> 177825 | O14: =Model!O239+N14 -> 177825 | P14: =Model!P239+O14 -> 177825 | Q14: =Model!Q239+P14 -> 177825 | R14: =Model!R239+Q14 -> 177825 | ... BR14: =Model!BR239+BQ14 -> 177825
B15: Accumulated Depreciation | E15: =INDEX($K15:$BR15,,MATCH(E$2,$K$2:$BR$2,0)+11) -> -44456.25 | F15: =INDEX($K15:$BR15,,MATCH(F$2,$K$2:$BR$2,0)+11) -> -88912.5 | G15: =INDEX($K15:$BR15,,MATCH(G$2,$K$2:$BR$2,0)+11) -> -133368.75 | H15: =INDEX($K15:$BR15,,MATCH(H$2,$K$2:$BR$2,0)+11) -> -177825 | I15: =INDEX($K15:$BR15,,MATCH(I$2,$K$2:$BR$2,0)+11) -> -177825 | K15: =Model!K241+J15 -> -3704.6875 | L15: =Model!L241+K15 -> -7409.375 | M15: =Model!M241+L15 -> -11114.062 | N15: =Model!N241+M15 -> -14818.75 | O15: =Model!O241+N15 -> -18523.438 | P15: =Model!P241+O15 -> -22228.125 | Q15: =Model!Q241+P15 -> -25932.812 | R15: =Model!R241+Q15 -> -29637.5 | ... BR15: =Model!BR241+BQ15 -> -177825
B17: Net book value of fixed assets | E17: =SUM(E14:E15) -> 133368.75 | F17: =SUM(F14:F15) -> 88912.5 | G17: =SUM(G14:G15) -> 44456.25 | H17: =SUM(H14:H15) -> 0 | I17: =SUM(I14:I15) -> 0 | K17: =SUM(K14:K15) -> 174120.31 | L17: =SUM(L14:L15) -> 170415.62 | M17: =SUM(M14:M15) -> 166710.94 | N17: =SUM(N14:N15) -> 163006.25 | O17: =SUM(O14:O15) -> 159301.56 | P17: =SUM(P14:P15) -> 155596.88 | Q17: =SUM(Q14:Q15) -> 151892.19 | R17: =SUM(R14:R15) -> 148187.5 | ... BR17: =SUM(BR14:BR15) -> 0
B19: Other Assets
B20: Other Assets | E20: =INDEX($K20:$BR20,,MATCH(E$2,$K$2:$BR$2,0)+11) -> 0 | F20: =INDEX($K20:$BR20,,MATCH(F$2,$K$2:$BR$2,0)+11) -> 0 | G20: =INDEX($K20:$BR20,,MATCH(G$2,$K$2:$BR$2,0)+11) -> 0 | H20: =INDEX($K20:$BR20,,MATCH(H$2,$K$2:$BR$2,0)+11) -> 0 | I20: =INDEX($K20:$BR20,,MATCH(I$2,$K$2:$BR$2,0)+11) -> 0 | K20: 0 | L20: 0 | M20: 0 | N20: 0 | O20: 0 | P20: 0 | Q20: 0 | R20: 0 | S20: 0 | T20: 0 | U20: 0 | V20: 0 | W20: 0 | X20: 0 | Y20: 0 | Z20: 0 | AA20: 0 | AB20: 0 | AC20: 0 | AD20: 0 | AE20: 0 | AF20: 0 | AG20: 0 | AH20: 0 | AI20: 0 | AJ20: 0 | AK20: 0 | AL20: 0 | AM20: 0 | AN20: 0 | AO20: 0 | AP20: 0 | AQ20: 0 | AR20: 0 | AS20: 0 | AT20: 0 | AU20: 0 | AV20: 0 | AW20: 0 | AX20: 0 | AY20: 0 | AZ20: 0 | BA20: 0 | BB20: 0 | BC20: 0 | BD20: 0 | BE20: 0 | BF20: 0 | BG20: 0 | BH20: 0 | BI20: 0 | BJ20: 0 | BK20: 0 | BL20: 0 | BM20: 0 | BN20: 0 | BO20: 0 | BP20: 0 | BQ20: 0 | BR20: 0
B21: Total Other Assets | E21: =SUM(E20) -> 0 | F21: =SUM(F20) -> 0 | G21: =SUM(G20) -> 0 | H21: =SUM(H20) -> 0 | I21: =SUM(I20) -> 0 | K21: =SUM(K20) -> 0 | L21: =SUM(L20) -> 0 | M21: =SUM(M20) -> 0 | N21: =SUM(N20) -> 0 | O21: =SUM(O20) -> 0 | P21: =SUM(P20) -> 0 | Q21: =SUM(Q20) -> 0 | R21: =SUM(R20) -> 0 | ... BR21: =SUM(BR20) -> 0
B23: Total Assets | E23: =E11+E17+E21 -> 199293.17 | F23: =F11+F17+F21 -> 169887.92 | G23: =G11+G17+G21 -> 162527.95 | H23: =H11+H17+H21 -> 166401.19 | I23: =I11+I17+I21 -> 226287 | K23: =K11+K17+K20 -> 293426.86 | L23: =L11+L17+L21 -> 282769.38 | M23: =M11+M17+M21 -> 271666.43 | N23: =N11+N17+N21 -> 261175.78 | O23: =O11+O17+O21 -> 251297.42 | P23: =P11+P17+P21 -> 242031.36 | Q23: =Q11+Q17+Q21 -> 233377.59 | R23: =R11+R17+R21 -> 225336.12 | S23: =S11+S17+S21 -> 217906.94 | ... BR23: =BR11+BR17+BR21 -> 226287
B25: LIABILITIES AND SHAREHOLDERS' EQUITY
B27: Current liabilities:
B28: Accounts Payable | E28: =INDEX($K28:$BR28,,MATCH(E$2,$K$2:$BR$2,0)+11) -> 20853.096 | F28: =INDEX($K28:$BR28,,MATCH(F$2,$K$2:$BR$2,0)+11) -> 29016.25 | G28: =INDEX($K28:$BR28,,MATCH(G$2,$K$2:$BR$2,0)+11) -> 32054.631 | H28: =INDEX($K28:$BR28,,MATCH(H$2,$K$2:$BR$2,0)+11) -> 34715.149 | I28: =INDEX($K28:$BR28,,MATCH(I$2,$K$2:$BR$2,0)+11) -> 37596.49 | K28: =Model!K103 -> 8159.9071 | L28: =Model!L103 -> 10275.439 | M28: =Model!M103 -> 11333.204 | N28: =Model!N103 -> 12390.97 | O28: =Model!O103 -> 13448.736 | P28: =Model!P103 -> 14506.502 | Q28: =Model!Q103 -> 15564.267 | R28: =Model!R103 -> 16622.033 | ... BR28: =Model!BR103 -> 37596.49
B29: Tax Payable | E29: =INDEX($K29:$BR29,,MATCH(E$2,$K$2:$BR$2,0)+11) -> 0 | F29: =INDEX($K29:$BR29,,MATCH(F$2,$K$2:$BR$2,0)+11) -> 0 | G29: =INDEX($K29:$BR29,,MATCH(G$2,$K$2:$BR$2,0)+11) -> 0 | H29: =INDEX($K29:$BR29,,MATCH(H$2,$K$2:$BR$2,0)+11) -> 0 | I29: =INDEX($K29:$BR29,,MATCH(I$2,$K$2:$BR$2,0)+11) -> 0 | K29: =Model!K104 -> 0 | L29: =Model!L104 -> 0 | M29: =Model!M104 -> 0 | N29: =Model!N104 -> 0 | O29: =Model!O104 -> 0 | P29: =Model!P104 -> 0 | Q29: =Model!Q104 -> 0 | R29: =Model!R104 -> 0 | ... BR29: =Model!BR104 -> 0
B30: Credit Card Payable | E30: =INDEX($K30:$BR30,,MATCH(E$2,$K$2:$BR$2,0)+11) -> 0 | F30: =INDEX($K30:$BR30,,MATCH(F$2,$K$2:$BR$2,0)+11) -> 0 | G30: =INDEX($K30:$BR30,,MATCH(G$2,$K$2:$BR$2,0)+11) -> 0 | H30: =INDEX($K30:$BR30,,MATCH(H$2,$K$2:$BR$2,0)+11) -> 0 | I30: =INDEX($K30:$BR30,,MATCH(I$2,$K$2:$BR$2,0)+11) -> 0 | K30: 0 | L30: 0 | M30: 0 | N30: 0 | O30: 0 | P30: 0 | Q30: 0 | R30: 0 | S30: 0 | T30: 0 | U30: 0 | V30: 0 | W30: 0 | X30: 0 | Y30: 0 | Z30: 0 | AA30: 0 | AB30: 0 | AC30: 0 | AD30: 0 | AE30: 0 | AF30: 0 | AG30: 0 | AH30: 0 | AI30: 0 | AJ30: 0 | AK30: 0 | AL30: 0 | AM30: 0 | AN30: 0 | AO30: 0 | AP30: 0 | AQ30: 0 | AR30: 0 | AS30: 0 | AT30: 0 | AU30: 0 | AV30: 0 | AW30: 0 | AX30: 0 | AY30: 0 | AZ30: 0 | BA30: 0 | BB30: 0 | BC30: 0 | BD30: 0 | BE30: 0 | BF30: 0 | BG30: 0 | BH30: 0 | BI30: 0 | BJ30: 0 | BK30: 0 | BL30: 0 | BM30: 0 | BN30: 0 | BO30: 0 | BP30: 0 | BQ30: 0 | BR30: 0
B31: Line of Credit | E31: =INDEX($K31:$BR31,,MATCH(E$2,$K$2:$BR$2,0)+11) -> 0 | F31: =INDEX($K31:$BR31,,MATCH(F$2,$K$2:$BR$2,0)+11) -> 0 | G31: =INDEX($K31:$BR31,,MATCH(G$2,$K$2:$BR$2,0)+11) -> 0 | H31: =INDEX($K31:$BR31,,MATCH(H$2,$K$2:$BR$2,0)+11) -> 0 | I31: =INDEX($K31:$BR31,,MATCH(I$2,$K$2:$BR$2,0)+11) -> 0 | K31: 0 | L31: 0 | M31: 0 | N31: 0 | O31: 0 | P31: 0 | Q31: 0 | R31: 0 | S31: 0 | T31: 0 | U31: 0 | V31: 0 | W31: 0 | X31: 0 | Y31: 0 | Z31: 0 | AA31: 0 | AB31: 0 | AC31: 0 | AD31: 0 | AE31: 0 | AF31: 0 | AG31: 0 | AH31: 0 | AI31: 0 | AJ31: 0 | AK31: 0 | AL31: 0 | AM31: 0 | AN31: 0 | AO31: 0 | AP31: 0 | AQ31: 0 | AR31: 0 | AS31: 0 | AT31: 0 | AU31: 0 | AV31: 0 | AW31: 0 | AX31: 0 | AY31: 0 | AZ31: 0 | BA31: 0 | BB31: 0 | BC31: 0 | BD31: 0 | BE31: 0 | BF31: 0 | BG31: 0 | BH31: 0 | BI31: 0 | BJ31: 0 | BK31: 0 | BL31: 0 | BM31: 0 | BN31: 0 | BO31: 0 | BP31: 0 | BQ31: 0 | BR31: 0
B33: Total current liabilities | E33: =SUM(E28:E32) -> 20853.096 | F33: =SUM(F28:F32) -> 29016.25 | G33: =SUM(G28:G32) -> 32054.631 | H33: =SUM(H28:H32) -> 34715.149 | I33: =SUM(I28:I32) -> 37596.49 | K33: =SUM(K28:K32) -> 8159.9071 | L33: =SUM(L28:L32) -> 10275.439 | M33: =SUM(M28:M32) -> 11333.204 | N33: =SUM(N28:N32) -> 12390.97 | O33: =SUM(O28:O32) -> 13448.736 | P33: =SUM(P28:P32) -> 14506.502 | Q33: =SUM(Q28:Q32) -> 15564.267 | R33: =SUM(R28:R32) -> 16622.033 | ... BR33: =SUM(BR28:BR32) -> 37596.49
B35: Long-term liabilities:
B36: Notes Payable | E36: =INDEX($K36:$BR36,,MATCH(E$2,$K$2:$BR$2,0)+11) -> 219450 | F36: =INDEX($K36:$BR36,,MATCH(F$2,$K$2:$BR$2,0)+11) -> 199500 | G36: =INDEX($K36:$BR36,,MATCH(G$2,$K$2:$BR$2,0)+11) -> 179550 | H36: =INDEX($K36:$BR36,,MATCH(H$2,$K$2:$BR$2,0)+11) -> 159600 | I36: =INDEX($K36:$BR36,,MATCH(I$2,$K$2:$BR$2,0)+11) -> 139650 | K36: =Model!K107 -> 237737.5 | L36: =Model!L107 -> 236075 | M36: =Model!M107 -> 234412.5 | N36: =Model!N107 -> 232750 | O36: =Model!O107 -> 231087.5 | P36: =Model!P107 -> 229425 | Q36: =Model!Q107 -> 227762.5 | R36: =Model!R107 -> 226100 | ... BR36: =Model!BR107 -> 139650
B38: Total long-term liabilities | E38: =SUM(E36) -> 219450 | F38: =SUM(F36) -> 199500 | G38: =SUM(G36) -> 179550 | H38: =SUM(H36) -> 159600 | I38: =SUM(I36) -> 139650 | K38: =SUM(K36) -> 237737.5 | L38: =SUM(L36) -> 236075 | M38: =SUM(M36) -> 234412.5 | N38: =SUM(N36) -> 232750 | O38: =SUM(O36) -> 231087.5 | P38: =SUM(P36) -> 229425 | Q38: =SUM(Q36) -> 227762.5 | R38: =SUM(R36) -> 226100 | ... BR38: =SUM(BR36) -> 139650
B40: Total Liabilities | E40: =E33+E38 -> 240303.1 | F40: =F33+F38 -> 228516.25 | G40: =G33+G38 -> 211604.63 | H40: =H33+H38 -> 194315.15 | I40: =I33+I38 -> 177246.49 | K40: =K33+K38 -> 245897.41 | L40: =L33+L38 -> 246350.44 | M40: =M33+M38 -> 245745.7 | N40: =N33+N38 -> 245140.97 | O40: =O33+O38 -> 244536.24 | P40: =P33+P38 -> 243931.5 | Q40: =Q33+Q38 -> 243326.77 | R40: =R33+R38 -> 242722.03 | ... BR40: =BR33+BR38 -> 177246.49
B42: Capital
B43: Common stock | E43: =INDEX($K43:$BR43,,MATCH(E$2,$K$2:$BR$2,0)+11) -> 59850 | F43: =INDEX($K43:$BR43,,MATCH(F$2,$K$2:$BR$2,0)+11) -> 59850 | G43: =INDEX($K43:$BR43,,MATCH(G$2,$K$2:$BR$2,0)+11) -> 59850 | H43: =INDEX($K43:$BR43,,MATCH(H$2,$K$2:$BR$2,0)+11) -> 59850 | I43: =INDEX($K43:$BR43,,MATCH(I$2,$K$2:$BR$2,0)+11) -> 59850 | K43: =Model!K114 -> 59850 | L43: =Model!L114 -> 59850 | M43: =Model!M114 -> 59850 | N43: =Model!N114 -> 59850 | O43: =Model!O114 -> 59850 | P43: =Model!P114 -> 59850 | Q43: =Model!Q114 -> 59850 | R43: =Model!R114 -> 59850 | ... BR43: =Model!BR114 -> 59850
B44: Retained earnings | E44: =INDEX($K44:$BR44,,MATCH(E$2,$K$2:$BR$2,0)+11) -> -100859.92 | F44: =INDEX($K44:$BR44,,MATCH(F$2,$K$2:$BR$2,0)+11) -> -118478.33 | G44: =INDEX($K44:$BR44,,MATCH(G$2,$K$2:$BR$2,0)+11) -> -108926.68 | H44: =INDEX($K44:$BR44,,MATCH(H$2,$K$2:$BR$2,0)+11) -> -87763.955 | I44: =INDEX($K44:$BR44,,MATCH(I$2,$K$2:$BR$2,0)+11) -> -10809.487 | K44: =Model!K115 -> -12320.55 | L44: =Model!L115 -> -23431.057 | M44: =Model!M115 -> -33929.27 | N44: =Model!N115 -> -43815.188 | O44: =Model!O115 -> -53088.811 | P44: =Model!P115 -> -61750.14 | Q44: =Model!Q115 -> -69799.174 | R44: =Model!R115 -> -77235.913 | ... BR44: =Model!BR115 -> -10809.487
B46: Total Capital | E46: =SUM(E43:E44) -> -41009.923 | F46: =SUM(F43:F44) -> -58628.332 | G46: =SUM(G43:G44) -> -49076.683 | H46: =SUM(H43:H44) -> -27913.955 | I46: =SUM(I43:I44) -> 49040.513 | K46: =SUM(K43:K44) -> 47529.45 | L46: =SUM(L43:L44) -> 36418.943 | M46: =SUM(M43:M44) -> 25920.73 | N46: =SUM(N43:N44) -> 16034.812 | O46: =SUM(O43:O44) -> 6761.1888 | P46: =SUM(P43:P44) -> -1900.1398 | Q46: =SUM(Q43:Q44) -> -9949.1736 | R46: =SUM(R43:R44) -> -17385.913 | ... BR46: =SUM(BR43:BR44) -> 49040.513
B48: Total liabilities and shareholders' equity | E48: =E40+E46 -> 199293.17 | F48: =F40+F46 -> 169887.92 | G48: =G40+G46 -> 162527.95 | H48: =H40+H46 -> 166401.19 | I48: =I40+I46 -> 226287 | K48: =K40+K46 -> 293426.86 | L48: =L40+L46 -> 282769.38 | M48: =M40+M46 -> 271666.43 | N48: =N40+N46 -> 261175.78 | O48: =O40+O46 -> 251297.42 | P48: =P40+P46 -> 242031.36 | Q48: =Q40+Q46 -> 233377.59 | R48: =R40+R46 -> 225336.12 | ... BR48: =BR40+BR46 -> 226287
B49: =SUM(E49:I49) -> 0 | E49: =ROUND(E23-E48,0) -> 0 | F49: =ROUND(F23-F48,0) -> 0 | G49: =ROUND(G23-G48,0) -> 0 | H49: =ROUND(H23-H48,0) -> 0 | I49: =ROUND(I23-I48,0) -> 0 | K49: =ROUND(K23-K48,0) -> 0 | L49: =ROUND(L23-L48,0) -> 0 | M49: =ROUND(M23-M48,0) -> 0 | N49: =ROUND(N23-N48,0) -> 0 | O49: =ROUND(O23-O48,0) -> 0 | P49: =ROUND(P23-P48,0) -> 0 | Q49: =ROUND(Q23-Q48,0) -> 0 | R49: =ROUND(R23-R48,0) -> 0 | ... BR49: =ROUND(BR23-BR48,0) -> 0
B51: A/R DSO (Based on last 2 months sales)
B52: A/P as % of COGS for this month and next month
B54: Core Capital | E54: =SUMIFS($K54:$BR54,$K$2:$BR$2,E$2)/12 -> 48376.397 | F54: =SUMIFS($K54:$BR54,$K$2:$BR$2,F$2)/12 -> 1654.0728 | G54: =SUMIFS($K54:$BR54,$K$2:$BR$2,G$2)/12 -> 18956.427 | H54: =SUMIFS($K54:$BR54,$K$2:$BR$2,H$2)/12 -> 55120.349 | I54: =SUMIFS($K54:$BR54,$K$2:$BR$2,I$2)/12 -> 102145.39 | K54: =K7-K31 -> 98240.291 | L54: =L7-L31 -> 85290.703 | M54: =M7-M31 -> 75696.812 | N54: =N7-N31 -> 65534.673 | O54: =O7-O31 -> 57275.556 | P54: =P7-P31 -> 48983.37 | Q54: =Q7-Q31 -> 38697.853 | R54: =R7-R31 -> 34235.882 | ... BR54: =BR7-BR31 -> 129224.97
B55: Core Capital target -Level 1 (1 month opex) | E55: =AVERAGEIFS($K55:$BR55,$K$2:$BR$2,E$2) -> 26826.397 | F55: =AVERAGEIFS($K55:$BR55,$K$2:$BR$2,F$2) -> 38559.734 | G55: =AVERAGEIFS($K55:$BR55,$K$2:$BR$2,G$2) -> 43306.994 | H55: =AVERAGEIFS($K55:$BR55,$K$2:$BR$2,H$2) -> 47101.301 | I55: =AVERAGEIFS($K55:$BR55,$K$2:$BR$2,I$2) -> 50817.639 | K55: ='P&L Statement'!K12+'P&L Statement'!K17+'P&L Statement'!K30 -> 19703.236 | L55: ='P&L Statement'!L12+'P&L Statement'!L17+'P&L Statement'!L30 -> 21923.442 | M55: ='P&L Statement'!M12+'P&L Statement'!M17+'P&L Statement'!M30 -> 23033.545 | N55: ='P&L Statement'!N12+'P&L Statement'!N17+'P&L Statement'!N30 -> 24143.648 | O55: ='P&L Statement'!O12+'P&L Statement'!O17+'P&L Statement'!O30 -> 25253.751 | P55: ='P&L Statement'!P12+'P&L Statement'!P17+'P&L Statement'!P30 -> 26363.854 | Q55: ='P&L Statement'!Q12+'P&L Statement'!Q17+'P&L Statement'!Q30 -> 27473.958 | R55: ='P&L Statement'!R12+'P&L Statement'!R17+'P&L Statement'!R30 -> 28584.061 | ... BR55: ='P&L Statement'!BR12+'P&L Statement'!BR17+'P&L Statement'!BR30 -> 52158.659
B56: Core Capital target -Level 2 (2 month opex) | E56: =AVERAGEIFS($K56:$BR56,$K$2:$BR$2,E$2) -> 53652.795 | F56: =AVERAGEIFS($K56:$BR56,$K$2:$BR$2,F$2) -> 77119.468 | G56: =AVERAGEIFS($K56:$BR56,$K$2:$BR$2,G$2) -> 86613.989 | H56: =AVERAGEIFS($K56:$BR56,$K$2:$BR$2,H$2) -> 94202.602 | I56: =AVERAGEIFS($K56:$BR56,$K$2:$BR$2,I$2) -> 101635.28 | K56: =K55*2 -> 39406.472 | L56: =L55*2 -> 43846.884 | M56: =M55*2 -> 46067.09 | N56: =N55*2 -> 48287.296 | O56: =O55*2 -> 50507.503 | P56: =P55*2 -> 52727.709 | Q56: =Q55*2 -> 54947.915 | R56: =R55*2 -> 57168.121 | ... BR56: =BR55*2 -> 104317.32
...

Sheet Cash Flow Statement
B1: =Company_Name -> ABC Company
B2: Cash Flow | E2: ='Input Assumptions'!E$18 -> 1 | F2: ='Input Assumptions'!F$18 -> 2 | G2: ='Input Assumptions'!G$18 -> 3 | H2: ='Input Assumptions'!H$18 -> 4 | I2: ='Input Assumptions'!I$18 -> 5 | K2: =IF(K$4<Fin_Year_End,1,IF(MONTH(K$4)=MONTH(Fin_Year_End)+1,MIN(J2+1,5),J2)) -> 1 | L2: =IF(L$4<Fin_Year_End,1,IF(MONTH(L$4)=MONTH(Fin_Year_End)+1,MIN(K2+1,5),K2)) -> 1 | M2: =IF(M$4<Fin_Year_End,1,IF(MONTH(M$4)=MONTH(Fin_Year_End)+1,MIN(L2+1,5),L2)) -> 1 | N2: =IF(N$4<Fin_Year_End,1,IF(MONTH(N$4)=MONTH(Fin_Year_End)+1,MIN(M2+1,5),M2)) -> 1 | O2: =IF(O$4<Fin_Year_End,1,IF(MONTH(O$4)=MONTH(Fin_Year_End)+1,MIN(N2+1,5),N2)) -> 1 | P2: =IF(P$4<Fin_Year_End,1,IF(MONTH(P$4)=MONTH(Fin_Year_End)+1,MIN(O2+1,5),O2)) -> 1 | Q2: =IF(Q$4<Fin_Year_End,1,IF(MONTH(Q$4)=MONTH(Fin_Year_End)+1,MIN(P2+1,5),P2)) -> 1 | R2: =IF(R$4<Fin_Year_End,1,IF(MONTH(R$4)=MONTH(Fin_Year_End)+1,MIN(Q2+1,5),Q2)) -> 1 | ... BR2: =IF(BR$4<Fin_Year_End,1,IF(MONTH(BR$4)=MONTH(Fin_Year_End)+1,MIN(BQ2+1,5),BQ2)) -> 5
E3: ='Input Assumptions'!E$17 -> 2024-2025 | F3: ='Input Assumptions'!F$17 -> 2025-2026 | G3: ='Input Assumptions'!G$17 -> 2026-2027 | H3: ='Input Assumptions'!H$17 -> 2027-2028 | I3: ='Input Assumptions'!I$17 -> 2028-2029
E4: =Model!E$12 -> Year 1 | F4: =Model!F$12 -> Year 2 | G4: =Model!G$12 -> Year 3 | H4: =Model!H$12 -> Year 4 | I4: =Model!I$12 -> Year 5 | K4: =EOMONTH(Start_Date,-1)+1 -> 45505 | L4: =EOMONTH(K4,0)+1 -> 45536 | M4: =EOMONTH(L4,0)+1 -> 45566 | N4: =EOMONTH(M4,0)+1 -> 45597 | O4: =EOMONTH(N4,0)+1 -> 45627 | P4: =EOMONTH(O4,0)+1 -> 45658 | Q4: =EOMONTH(P4,0)+1 -> 45689 | R4: =EOMONTH(Q4,0)+1 -> 45717 | S4: =EOMONTH(R4,0)+1 -> 45748 | ... BR4: =EOMONTH(BQ4,0)+1 -> 47300
B5: Cash Flows from Operations
B7: Net Income | E7: =SUMIFS($K7:$BR7,$K$2:$BR$2,E$2) -> -100859.92 | F7: =SUMIFS($K7:$BR7,$K$2:$BR$2,F$2) -> -17618.409 | G7: =SUMIFS($K7:$BR7,$K$2:$BR$2,G$2) -> 9551.648 | H7: =SUMIFS($K7:$BR7,$K$2:$BR$2,H$2) -> 21162.728 | I7: =SUMIFS($K7:$BR7,$K$2:$BR$2,I$2) -> 76954.468 | K7: =Model!K123 -> -12320.55 | L7: =Model!L123 -> -11110.507 | M7: =Model!M123 -> -10498.213 | N7: =Model!N123 -> -9885.918 | O7: =Model!O123 -> -9273.6233 | P7: =Model!P123 -> -8661.3286 | Q7: =Model!Q123 -> -8049.0339 | R7: =Model!R123 -> -7436.7392 | ... BR7: =Model!BR123 -> 7314.7956
B9: Add Back:
B10: Depreciation | E10: =SUMIFS($K10:$BR10,$K$2:$BR$2,E$2) -> 44456.25 | F10: =SUMIFS($K10:$BR10,$K$2:$BR$2,F$2) -> 44456.25 | G10: =SUMIFS($K10:$BR10,$K$2:$BR$2,G$2) -> 44456.25 | H10: =SUMIFS($K10:$BR10,$K$2:$BR$2,H$2) -> 44456.25 | I10: =SUMIFS($K10:$BR10,$K$2:$BR$2,I$2) -> 0 | K10: =Model!K125 -> 3704.6875 | L10: =Model!L125 -> 3704.6875 | M10: =Model!M125 -> 3704.6875 | N10: =Model!N125 -> 3704.6875 | O10: =Model!O125 -> 3704.6875 | P10: =Model!P125 -> 3704.6875 | Q10: =Model!Q125 -> 3704.6875 | R10: =Model!R125 -> 3704.6875 | ... BR10: =Model!BR125 -> 0
B11: Changes in:
B12: Accounts receivable | E12: =SUMIFS($K12:$BR12,$K$2:$BR$2,E$2) -> -32582.962 | F12: =SUMIFS($K12:$BR12,$K$2:$BR$2,F$2) -> -12754.929 | G12: =SUMIFS($K12:$BR12,$K$2:$BR$2,G$2) -> -4747.4696 | H12: =SUMIFS($K12:$BR12,$K$2:$BR$2,H$2) -> -4157.0602 | I12: =SUMIFS($K12:$BR12,$K$2:$BR$2,I$2) -> -4502.0942 | K12: =Model!K127 -> -12749.855 | L12: =Model!L127 -> -3840.697 | M12: =Model!M127 -> -1117.5799 | N12: =Model!N127 -> -2298.122 | O12: =Model!O127 -> -1007.3959 | P12: =Model!P127 -> -1652.759 | Q12: =Model!Q127 -> -4258.3841 | R12: =Model!R127 -> 952.86614 | ... BR12: =Model!BR127 -> 1556.1461
B13: Other Current Assets | E13: =SUMIFS($K13:$BR13,$K$2:$BR$2,E$2) -> -21253.018 | F13: =SUMIFS($K13:$BR13,$K$2:$BR$2,F$2) -> -8319.708 | G13: =SUMIFS($K13:$BR13,$K$2:$BR$2,G$2) -> -3096.6509 | H13: =SUMIFS($K13:$BR13,$K$2:$BR$2,H$2) -> -2711.5422 | I13: =SUMIFS($K13:$BR13,$K$2:$BR$2,I$2) -> -2936.5989 | K13: =Model!K130 -> -8316.3985 | L13: =Model!L130 -> -2156.1033 | M13: =Model!M130 -> -1078.0517 | N13: =Model!N130 -> -1078.0517 | O13: =Model!O130 -> -1078.0517 | P13: =Model!P130 -> -1078.0517 | Q13: =Model!Q130 -> -1078.0517 | R13: =Model!R130 -> -1078.0517 | ... BR13: =Model!BR130 -> -253.7584
B14: Other Assets | E14: =SUMIFS($K14:$BR14,$K$2:$BR$2,E$2) -> 0 | F14: =SUMIFS($K14:$BR14,$K$2:$BR$2,F$2) -> 0 | G14: =SUMIFS($K14:$BR14,$K$2:$BR$2,G$2) -> 0 | H14: =SUMIFS($K14:$BR14,$K$2:$BR$2,H$2) -> 0 | I14: =SUMIFS($K14:$BR14,$K$2:$BR$2,I$2) -> 0
